
Utilisation du device: cpu

Tentative de chargement du modèle depuis saved_model...
Some weights of BertForQuestionAnswering were not initialized from the model checkpoint at bert-base-uncased and are newly initialized: ['qa_outputs.bias', 'qa_outputs.weight']
You should probably TRAIN this model on a down-stream task to be able to use it for predictions and inference.
Modèle chargé avec succès depuis le fichier sauvegardé

Loading dataset...

Taille du dataset d'entraînement: 9000
Taille du dataset de validation: 1000

Initializing MedicalQADataset with max_length=512
Dataset initialized with 9000 examples

Initializing MedicalQADataset with max_length=512
Dataset initialized with 1000 examples

Starting retraining process with 3 epochs...

Epoch 1/3
C:\Python312\Lib\site-packages\transformers\optimization.py:591: FutureWarning: This implementation of AdamW is deprecated and will be removed in a future version. Use the PyTorch implementation torch.optim.AdamW instead, or set `no_deprecation_warning=True` to disable this warning
  warnings.warn(

Epoch 1/1
Epoch 1/1:   0%|▎                                                                                                                                                | 2/1125 [01:42<16:06:15, 51.63s/it, loss=5.7974]Token indices sequence length is longer than the specified maximum sequence length for this model (1685 > 512). Running this sequence through the model will result in indexing errors
Epoch 1/1: 100%|██████████████████████████████████████████████████████████████████████████████████████████████████████████████████████████████████████████████| 1125/1125 [13:36:34<00:00, 43.55s/it, loss=0.0004]

Saving model for epoch 1 to retrain_epoch_1...
C:\Python312\Lib\site-packages\transformers\integrations\peft.py:418: FutureWarning: The `active_adapter` method is deprecated and will be removed in a future version.
  warnings.warn(

Epoch 2/3

Epoch 1/1
Epoch 1/1:   1%|▊                                                                                                                                                | 6/1125 [04:21<13:33:24, 43.61s/it, loss=0.0028]
Error in sys.excepthook:
Traceback (most recent call last):
  File "C:\Python312\Lib\site-packages\wandb\sdk\lib\exit_hooks.py", line 52, in exc_handler
    traceback.print_exception(exc_type, exc, tb)
  File "C:\Python312\Lib\traceback.py", line 124, in print_exception
    te = TracebackException(type(value), value, tb, limit=limit, compact=True)
         ^^^^^^^^^^^^^^^^^^^^^^^^^^^^^^^^^^^^^^^^^^^^^^^^^^^^^^^^^^^^^^^^^^^^^
  File "C:\Python312\Lib\traceback.py", line 707, in __init__
  File "C:\Python312\Lib\traceback.py", line 421, in _extract_from_extended_frame_gen
    for f, (lineno, end_lineno, colno, end_colno) in frame_gen:
  File "C:\Python312\Lib\traceback.py", line 358, in _walk_tb_with_full_positions
    positions = _get_code_position(tb.tb_frame.f_code, tb.tb_lasti)
                ^^^^^^^^^^^^^^^^^^^^^^^^^^^^^^^^^^^^^^^^^^^^^^^^^^^
  File "C:\Python312\Lib\traceback.py", line 372, in _get_code_position
    return next(itertools.islice(positions_gen, instruction_index // 2, None))
                ^^^^^^^^^^^^^^^^^^^^^^^^^^^^^^^^^^^^^^^^^^^^^^^^^^^^^^^^^^^^^
KeyboardInterrupt

Original exception was:
